<?xml version="1.0"?>
<robot name="xl_terabot" xmlns:xacro="http://www.ros.org/wiki/xacro"> 

  <!-- Import all Gazebo-customization elements, including Gazebo colors -->
  <!-- xacro:include filename="$(find xl_terabot_description)/urdf/xl_terabot.gazebo" / -->

  <!-- Robot mechanical and motor parameters -->
  <xacro:property name="PI" value="3.1415926535897931"/>

  <!-- BASE FOOTPRINT -->
  <!-- base_footprint is a fictitious link(frame) that is on the ground right below base_link origin,
             navigation stack depends on this frame -->
  <link name="base_footprint">
      <!-- inertial>
          <mass value="0.0001" />
          <origin xyz="0 0 0" />
      <inertia ixx="0.0001" ixy="0.0" ixz="0.0"
                         iyy="0.0001" iyz="0.0" 
                         izz="0.0001" />
      </inertial -->

      <visual>
          <origin xyz="0 0 0" rpy="0 0 0" />
          <geometry>
             <box size="0.001 0.001 0.001" />
          </geometry>
      </visual>

      <collision>
          <origin xyz="0 0 0" rpy="0 0 0" />
          <geometry>
            <box size="0.001 0.001 0.001" />
         </geometry>
     </collision>
  </link>

  <gazebo reference="base_footprint">
    <material>Gazebo/Green</material>
    <turnGravityOff>false</turnGravityOff>
  </gazebo>

  <joint name="base_footprint_joint" type="fixed">
     <!--NB: While you would think this would make it go up, it is oddly reversed.
      This moves the joint to 0,0,0 where we want it for rviz, etc. -->
     <!-- origin xyz="0 0 0" rpy="0 0 0" /-->
     <origin xyz="0 0 0.120" rpy="0 0 0" />
     <!-- origin xyz="0 0 0.150" rpy="0 0 0" / -->
     <!-- origin xyz="0 0 -0.050" rpy="0 0 0" /-->
     <parent link="base_footprint"/>
     <child link="base_link" />
  </joint>


  <!-- BASE_LINK (RED) -->

  <link name="base_link">
    <inertial>
      <mass value="25.0" />
      <origin xyz="0 0 0" />
      <inertia  ixx="1.391" ixy="0.004"  ixz="0.0"  iyy="6.853"  iyz="0.0"  izz="6.125" />
    </inertial>
    <visual>
       <origin xyz="0 0 0" rpy="0 0 0" />
       <geometry>
	 <mesh filename="package://xl_terabot_description/meshes/summit_xl_chassis_cam1.dae"/>
       </geometry>
    </visual>
    <collision>
       <origin xyz="0 0 0" rpy="0 0 0 " />
       <geometry>
         <mesh filename="package://xl_terabot_description/meshes/summit_xl_chassis_cam1.dae"/>
	 <box size = "0.750 0.4 0.3"/>
       </geometry>
    </collision>     
  </link>
  <gazebo reference="base_link">
    <material>Gazebo/Red</material>
    <turnGravityOff>false</turnGravityOff>
  </gazebo>


  <!-- BACK LEFT WHEEL (GREY) -->
  <link name="back_left_wheel">
    <inertial>
      <mass value="1.250" />
      <origin xyz="0 0 0" /> 
      <inertia  ixx="0.0109375" ixy="0.0"  ixz="0.0"  iyy="0.021125"  iyz="0.0"  izz="0.0109375" />
      <!--inertia ixx="1.0" ixy="0.0" ixz="0.0" iyy="1.0" iyz="0.0" izz="1.0"/-->
      <!--inertia  ixx="0.00584" ixy="0.0"  ixz="0.0"  iyy="0.00584"  iyz="0.0"  izz="0.01072"/-->
    </inertial>
    <visual>
       <origin xyz="0 0 0" rpy="0 0 0" /> 
       <geometry>
	 <mesh filename="package://xl_terabot_description/meshes/summit_xl_wheel.dae" scale="1.0 1.0 1.0"/>
         <!-- cylinder radius="0.125" length="0.1"/ -->
       </geometry>
	<material name="grey">
		<color rgba="0.5 0.5 0.5 1"/>
      	</material>
    </visual>
    <collision>
       <origin xyz="0 0 0" rpy="0 0 0" />
       <geometry>
	 <mesh filename="package://xl_terabot_description/meshes/summit_xl_wheel.dae" scale="1.0 1.0 1.0"/>
         <!-- cylinder radius="0.125" length="0.1"/ -->
       </geometry>
    </collision>
  </link>
  <gazebo reference="back_left_wheel">
    <mu1 value="100.0"/> <!-- 2.0 -->
    <mu2 value="100.0"/> <!-- 0.5 -->
    <fdir1 value="1 0 0"/>
    <material>Gazebo/Grey</material>
    <turnGravityOff>false</turnGravityOff>
  </gazebo>

  <joint name="joint_back_left_wheel" type="continuous">
    <parent link="base_link"/>
    <child link="back_left_wheel"/>
    <origin xyz="-0.223 0.154 0" rpy="0 0 0" /> 
    <axis xyz="0 1 0" rpy="0 0 0" />
    <limit effort="100" velocity="100"/>
    <joint_properties damping="0.0" friction="0.0"/>
  </joint>

  <transmission name="joint_blw_trans" type="pr2_mechanism_model/SimpleTransmission">
     <actuator name="joint_blw_motor" />
     <joint name="joint_back_left_wheel" />
     <mechanicalReduction>1</mechanicalReduction>
     <motorTorqueConstant>1</motorTorqueConstant>
  </transmission>


  <!-- BACK RIGHT WHEEL (GREY) -->
  <link name="back_right_wheel">
    <inertial>
      <mass value="1.250" />
      <origin xyz="0 0 0" />
      <inertia  ixx="0.0109375" ixy="0.0"  ixz="0.0"  iyy="0.021125"  iyz="0.0"  izz="0.0109375" />
    </inertial>
    <visual>
       <origin xyz="0 0 0" rpy="0 0 0" /> 
       <geometry>
	 <mesh filename="package://xl_terabot_description/meshes/summit_xl_wheel.dae" scale="1.0 1.0 1.0"/>
         <!-- cylinder radius="0.125" length="0.1"/ -->
       </geometry>
	<material name="grey">
		<color rgba="0.5 0.5 0.5 1"/>
      	</material>
    </visual>
    <collision>
       <origin xyz="0 0 0" rpy="0 0 0" /> 
       <geometry>        
	 <mesh filename="package://xl_terabot_description/meshes/summit_xl_wheel.dae" scale="1.0 1.0 1.0"/>
         <!-- cylinder radius="0.125" length="0.1"/ -->
       </geometry>
    </collision>
  </link>
  <gazebo reference="back_right_wheel">
    <mu1 value="100.0"/> <!-- 2.0 -->
    <mu2 value="100.0"/> <!-- 0.5 -->
    <fdir1 value="1 0 0"/>
    <material>Gazebo/Grey</material>
    <turnGravityOff>false</turnGravityOff>
  </gazebo>

  <joint name="joint_back_right_wheel" type="continuous">
    <parent link="base_link"/>
    <child link="back_right_wheel"/>
    <origin xyz="-0.223 -0.154 0" rpy="0 0 3.1416" />
    <axis xyz="0 1 0" />
    <limit effort="100" velocity="100"/>
    <joint_properties damping="0.0" friction="0.0"/>
  </joint>

  <transmission name="joint_brw_trans" type="pr2_mechanism_model/SimpleTransmission">
     <actuator name="joint_brw_motor" />
     <joint name="joint_back_right_wheel" />
     <mechanicalReduction>1</mechanicalReduction>
     <motorTorqueConstant>1</motorTorqueConstant>
  </transmission>


  <!-- FRONT LEFT WHEEL (GREY) -->
  <link name="front_left_wheel">
    <inertial>
      <mass value="1.250" />
      <origin xyz="0 0 0" />
      <inertia  ixx="0.0109375" ixy="0.0"  ixz="0.0"  iyy="0.021125"  iyz="0.0"  izz="0.0109375" />
    </inertial>
    <visual>
       <origin xyz="0 0 0" rpy="0 0 0" /> 
       <geometry>
	 <mesh filename="package://xl_terabot_description/meshes/summit_xl_wheel.dae" scale="1.0 1.0 1.0"/>
         <!-- cylinder radius="0.125" length="0.1"/ -->
       </geometry>
	<material name="grey">
		<color rgba="0.5 0.5 0.5 1"/>
      	</material>
    </visual>
    <collision>
       <origin xyz="0 0 0" rpy="0 0 0" /> 
       <geometry>
	 <mesh filename="package://xl_terabot_description/meshes/summit_xl_wheel.dae" scale="1.0 1.0 1.0"/>
         <!-- cylinder radius="0.125" length="0.1"/ -->
       </geometry>
    </collision>
  </link>
  <gazebo reference="front_left_wheel">
    <mu1 value="100.0"/> <!-- 2.0 -->
    <mu2 value="100.0"/> <!-- 0.5 -->
    <fdir1 value="1 0 0"/>
    <material>Gazebo/Grey</material>
    <turnGravityOff>false</turnGravityOff>
  </gazebo>

  <joint name="joint_front_left_wheel" type="continuous">
    <parent link="base_link"/>
    <child link="front_left_wheel"/>
    <origin xyz="0.223 0.154 0" rpy="0 0 0" />
    <axis xyz="0 1 0" />
    <limit effort="100" velocity="100"/>
    <joint_properties damping="0.0" friction="0.0"/>
  </joint>

  <transmission name="joint_flw_trans" type="pr2_mechanism_model/SimpleTransmission">
     <actuator name="joint_flw_motor" />
     <joint name="joint_front_left_wheel" />
     <mechanicalReduction>1</mechanicalReduction>
     <motorTorqueConstant>1</motorTorqueConstant>
  </transmission>


  <!-- FRONT RIGHT WHEEL (GREY) -->
  <link name="front_right_wheel">
    <inertial>
      <mass value="1.250" />
      <origin xyz="0 0 0" />
      <inertia  ixx="0.0109375" ixy="0.0"  ixz="0.0"  iyy="0.021125"  iyz="0.0"  izz="0.0109375" />
    </inertial>
    <visual>
       <origin xyz="0 0 0" rpy="0 0 0" /> 
       <geometry>
	 <mesh filename="package://xl_terabot_description/meshes/summit_xl_wheel.dae" scale="1.0 1.0 1.0"/>
         <!-- cylinder radius="0.125" length="0.1"/ -->
       </geometry>
	<material name="grey">
		<color rgba="0.5 0.5 0.5 1"/>
      	</material>
    </visual>
    <collision>
       <origin xyz="0 0 0" rpy="0 0 0" /> 
       <geometry>
	 <mesh filename="package://xl_terabot_description/meshes/summit_xl_wheel.dae" scale="1.0 1.0 1.0"/>
         <!-- cylinder radius="0.125" length="0.1"/ -->
       </geometry>
    </collision>
  </link>
  <gazebo reference="front_right_wheel">
    <mu1 value="100.0"/> <!-- 2.0 -->
    <mu2 value="100.0"/> <!-- 0.5 -->
    <fdir1 value="1 0 0"/>
    <material>Gazebo/Grey</material>
    <turnGravityOff>false</turnGravityOff>
  </gazebo>

  <joint name="joint_front_right_wheel" type="continuous">
    <parent link="base_link"/>
    <child link="front_right_wheel"/>
    <origin xyz="0.223 -0.154 0" rpy="0 0 3.1416" />
    <axis xyz="0 1 0" />
    <limit effort="100" velocity="100"/>
    <joint_properties damping="0.0" friction="0.0"/>
  </joint>

  <transmission name="joint_frw_trans" type="pr2_mechanism_model/SimpleTransmission">
     <actuator name="joint_frw_motor" />
     <joint name="joint_front_right_wheel" />
     <mechanicalReduction>1</mechanicalReduction>
     <motorTorqueConstant>1</motorTorqueConstant>
  </transmission>


  <!-- Base of the Terabot on the XL -->
  <!-- Import Terabot arm xacro file description -->
  <xacro:include filename="$(find terabot_description)/urdf/terabot.xacro" />

  <joint name="base_footprint_terabot_joint" type="fixed">
     <!-- origin xyz="-0.220 0 0.410" rpy="0 0 0" / -->
     <origin xyz="0.0 0.0 0.265" rpy="0 0 0" />
     <parent link="base_link"/>
     <child link="base_link_terabot"/>
  </joint>  

</robot>

