<?xml version="1.0" ?>
<!-- =================================================================================== -->
<!-- |    This document was autogenerated by xacro from xl_terabot.urdf.xacro          | -->
<!-- |    EDITING THIS FILE BY HAND IS NOT RECOMMENDED                                 | -->
<!-- =================================================================================== -->
<robot name="xl_terabot" xmlns:xacro="http://www.ros.org/wiki/xacro">
  <!-- Import all Gazebo-customization elements, including Gazebo colors -->
  <!-- xacro:include filename="$(find xl_terabot_description)/urdf/xl_terabot.gazebo" / -->
  <!-- Robot mechanical and motor parameters -->
  <!-- BASE FOOTPRINT -->
  <!-- base_footprint is a fictitious link(frame) that is on the ground right below base_link origin,
             navigation stack depends on this frame -->
  <link name="base_footprint">
    <!-- inertial>
          <mass value="0.0001" />
          <origin xyz="0 0 0" />
      <inertia ixx="0.0001" ixy="0.0" ixz="0.0"
                         iyy="0.0001" iyz="0.0" 
                         izz="0.0001" />
      </inertial -->
    <visual>
      <origin rpy="0 0 0" xyz="0 0 0"/>
      <geometry>
        <box size="0.001 0.001 0.001"/>
      </geometry>
    </visual>
    <collision>
      <origin rpy="0 0 0" xyz="0 0 0"/>
      <geometry>
        <box size="0.001 0.001 0.001"/>
      </geometry>
    </collision>
  </link>
  <gazebo reference="base_footprint">
    <material>Gazebo/Green</material>
    <turnGravityOff>false</turnGravityOff>
  </gazebo>
  <joint name="base_footprint_joint" type="fixed">
    <!--NB: While you would think this would make it go up, it is oddly reversed.
      This moves the joint to 0,0,0 where we want it for rviz, etc. -->
    <!-- origin xyz="0 0 0" rpy="0 0 0" /-->
    <origin rpy="0 0 0" xyz="0 0 0.120"/>
    <!-- origin xyz="0 0 0.150" rpy="0 0 0" / -->
    <!-- origin xyz="0 0 -0.050" rpy="0 0 0" /-->
    <parent link="base_footprint"/>
    <child link="base_link"/>
  </joint>
  <!-- BASE_LINK (RED) -->
  <link name="base_link">
    <inertial>
      <mass value="25.0"/>
      <origin xyz="0 0 0"/>
      <inertia ixx="1.391" ixy="0.004" ixz="0.0" iyy="6.853" iyz="0.0" izz="6.125"/>
    </inertial>
    <visual>
      <origin rpy="0 0 0" xyz="0 0 0"/>
      <geometry>
        <mesh filename="package://xl_terabot_description/meshes/summit_xl_chassis_cam1.dae"/>
      </geometry>
    </visual>
    <collision>
      <origin rpy="0 0 0 " xyz="0 0 0"/>
      <geometry>
        <mesh filename="package://xl_terabot_description/meshes/summit_xl_chassis_cam1.dae"/>
        <box size="0.750 0.4 0.3"/>
      </geometry>
    </collision>
  </link>
  <gazebo reference="base_link">
    <material>Gazebo/Red</material>
    <turnGravityOff>false</turnGravityOff>
  </gazebo>
  <!-- BACK LEFT WHEEL (GREY) -->
  <link name="back_left_wheel">
    <inertial>
      <mass value="1.250"/>
      <origin xyz="0 0 0"/>
      <inertia ixx="0.0109375" ixy="0.0" ixz="0.0" iyy="0.021125" iyz="0.0" izz="0.0109375"/>
      <!--inertia ixx="1.0" ixy="0.0" ixz="0.0" iyy="1.0" iyz="0.0" izz="1.0"/-->
      <!--inertia  ixx="0.00584" ixy="0.0"  ixz="0.0"  iyy="0.00584"  iyz="0.0"  izz="0.01072"/-->
    </inertial>
    <visual>
      <origin rpy="0 0 0" xyz="0 0 0"/>
      <geometry>
        <mesh filename="package://xl_terabot_description/meshes/summit_xl_wheel.dae" scale="1.0 1.0 1.0"/>
        <!-- cylinder radius="0.125" length="0.1"/ -->
      </geometry>
      <material name="grey">
        <color rgba="0.5 0.5 0.5 1"/>
      </material>
    </visual>
    <collision>
      <origin rpy="0 0 0" xyz="0 0 0"/>
      <geometry>
        <mesh filename="package://xl_terabot_description/meshes/summit_xl_wheel.dae" scale="1.0 1.0 1.0"/>
        <!-- cylinder radius="0.125" length="0.1"/ -->
      </geometry>
    </collision>
  </link>
  <gazebo reference="back_left_wheel">
    <mu1 value="100.0"/>
    <!-- 2.0 -->
    <mu2 value="100.0"/>
    <!-- 0.5 -->
    <fdir1 value="1 0 0"/>
    <material>Gazebo/Grey</material>
    <turnGravityOff>false</turnGravityOff>
  </gazebo>
  <joint name="joint_back_left_wheel" type="continuous">
    <parent link="base_link"/>
    <child link="back_left_wheel"/>
    <origin rpy="0 0 0" xyz="-0.223 0.154 0"/>
    <axis rpy="0 0 0" xyz="0 1 0"/>
    <limit effort="100" velocity="100"/>
    <joint_properties damping="0.0" friction="0.0"/>
  </joint>
  <transmission name="joint_blw_trans" type="pr2_mechanism_model/SimpleTransmission">
    <actuator name="joint_blw_motor"/>
    <joint name="joint_back_left_wheel"/>
    <mechanicalReduction>1</mechanicalReduction>
    <motorTorqueConstant>1</motorTorqueConstant>
  </transmission>
  <!-- BACK RIGHT WHEEL (GREY) -->
  <link name="back_right_wheel">
    <inertial>
      <mass value="1.250"/>
      <origin xyz="0 0 0"/>
      <inertia ixx="0.0109375" ixy="0.0" ixz="0.0" iyy="0.021125" iyz="0.0" izz="0.0109375"/>
    </inertial>
    <visual>
      <origin rpy="0 0 0" xyz="0 0 0"/>
      <geometry>
        <mesh filename="package://xl_terabot_description/meshes/summit_xl_wheel.dae" scale="1.0 1.0 1.0"/>
        <!-- cylinder radius="0.125" length="0.1"/ -->
      </geometry>
      <material name="grey">
        <color rgba="0.5 0.5 0.5 1"/>
      </material>
    </visual>
    <collision>
      <origin rpy="0 0 0" xyz="0 0 0"/>
      <geometry>
        <mesh filename="package://xl_terabot_description/meshes/summit_xl_wheel.dae" scale="1.0 1.0 1.0"/>
        <!-- cylinder radius="0.125" length="0.1"/ -->
      </geometry>
    </collision>
  </link>
  <gazebo reference="back_right_wheel">
    <mu1 value="100.0"/>
    <!-- 2.0 -->
    <mu2 value="100.0"/>
    <!-- 0.5 -->
    <fdir1 value="1 0 0"/>
    <material>Gazebo/Grey</material>
    <turnGravityOff>false</turnGravityOff>
  </gazebo>
  <joint name="joint_back_right_wheel" type="continuous">
    <parent link="base_link"/>
    <child link="back_right_wheel"/>
    <origin rpy="0 0 3.1416" xyz="-0.223 -0.154 0"/>
    <axis xyz="0 1 0"/>
    <limit effort="100" velocity="100"/>
    <joint_properties damping="0.0" friction="0.0"/>
  </joint>
  <transmission name="joint_brw_trans" type="pr2_mechanism_model/SimpleTransmission">
    <actuator name="joint_brw_motor"/>
    <joint name="joint_back_right_wheel"/>
    <mechanicalReduction>1</mechanicalReduction>
    <motorTorqueConstant>1</motorTorqueConstant>
  </transmission>
  <!-- FRONT LEFT WHEEL (GREY) -->
  <link name="front_left_wheel">
    <inertial>
      <mass value="1.250"/>
      <origin xyz="0 0 0"/>
      <inertia ixx="0.0109375" ixy="0.0" ixz="0.0" iyy="0.021125" iyz="0.0" izz="0.0109375"/>
    </inertial>
    <visual>
      <origin rpy="0 0 0" xyz="0 0 0"/>
      <geometry>
        <mesh filename="package://xl_terabot_description/meshes/summit_xl_wheel.dae" scale="1.0 1.0 1.0"/>
        <!-- cylinder radius="0.125" length="0.1"/ -->
      </geometry>
      <material name="grey">
        <color rgba="0.5 0.5 0.5 1"/>
      </material>
    </visual>
    <collision>
      <origin rpy="0 0 0" xyz="0 0 0"/>
      <geometry>
        <mesh filename="package://xl_terabot_description/meshes/summit_xl_wheel.dae" scale="1.0 1.0 1.0"/>
        <!-- cylinder radius="0.125" length="0.1"/ -->
      </geometry>
    </collision>
  </link>
  <gazebo reference="front_left_wheel">
    <mu1 value="100.0"/>
    <!-- 2.0 -->
    <mu2 value="100.0"/>
    <!-- 0.5 -->
    <fdir1 value="1 0 0"/>
    <material>Gazebo/Grey</material>
    <turnGravityOff>false</turnGravityOff>
  </gazebo>
  <joint name="joint_front_left_wheel" type="continuous">
    <parent link="base_link"/>
    <child link="front_left_wheel"/>
    <origin rpy="0 0 0" xyz="0.223 0.154 0"/>
    <axis xyz="0 1 0"/>
    <limit effort="100" velocity="100"/>
    <joint_properties damping="0.0" friction="0.0"/>
  </joint>
  <transmission name="joint_flw_trans" type="pr2_mechanism_model/SimpleTransmission">
    <actuator name="joint_flw_motor"/>
    <joint name="joint_front_left_wheel"/>
    <mechanicalReduction>1</mechanicalReduction>
    <motorTorqueConstant>1</motorTorqueConstant>
  </transmission>
  <!-- FRONT RIGHT WHEEL (GREY) -->
  <link name="front_right_wheel">
    <inertial>
      <mass value="1.250"/>
      <origin xyz="0 0 0"/>
      <inertia ixx="0.0109375" ixy="0.0" ixz="0.0" iyy="0.021125" iyz="0.0" izz="0.0109375"/>
    </inertial>
    <visual>
      <origin rpy="0 0 0" xyz="0 0 0"/>
      <geometry>
        <mesh filename="package://xl_terabot_description/meshes/summit_xl_wheel.dae" scale="1.0 1.0 1.0"/>
        <!-- cylinder radius="0.125" length="0.1"/ -->
      </geometry>
      <material name="grey">
        <color rgba="0.5 0.5 0.5 1"/>
      </material>
    </visual>
    <collision>
      <origin rpy="0 0 0" xyz="0 0 0"/>
      <geometry>
        <mesh filename="package://xl_terabot_description/meshes/summit_xl_wheel.dae" scale="1.0 1.0 1.0"/>
        <!-- cylinder radius="0.125" length="0.1"/ -->
      </geometry>
    </collision>
  </link>
  <gazebo reference="front_right_wheel">
    <mu1 value="100.0"/>
    <!-- 2.0 -->
    <mu2 value="100.0"/>
    <!-- 0.5 -->
    <fdir1 value="1 0 0"/>
    <material>Gazebo/Grey</material>
    <turnGravityOff>false</turnGravityOff>
  </gazebo>
  <joint name="joint_front_right_wheel" type="continuous">
    <parent link="base_link"/>
    <child link="front_right_wheel"/>
    <origin rpy="0 0 3.1416" xyz="0.223 -0.154 0"/>
    <axis xyz="0 1 0"/>
    <limit effort="100" velocity="100"/>
    <joint_properties damping="0.0" friction="0.0"/>
  </joint>
  <transmission name="joint_frw_trans" type="pr2_mechanism_model/SimpleTransmission">
    <actuator name="joint_frw_motor"/>
    <joint name="joint_front_right_wheel"/>
    <mechanicalReduction>1</mechanicalReduction>
    <motorTorqueConstant>1</motorTorqueConstant>
  </transmission>
  <!-- Base of the Terabot on the XL -->
  <!-- Import Terabot arm xacro file description -->
  <gazebo>
    <plugin filename="libgazebo_ros_control.so" name="ros_control">
      <robotNamespace>/terabot</robotNamespace>
      <controlPeriod>0.002</controlPeriod>
      <robotSimType>gazebo_ros_control/DefaultRobotHWSim</robotSimType>
    </plugin>
  </gazebo>
  <gazebo reference="base_link_terabot">
    <material>Gazebo/Black</material>
  </gazebo>
  <gazebo reference="Link1_terabot">
    <material>Gazebo/Grey</material>
    <gravity>true</gravity>
  </gazebo>
  <gazebo reference="Link2_terabot">
    <material>Gazebo/Black</material>
    <gravity>true</gravity>
  </gazebo>
  <gazebo reference="Link3_terabot">
    <material>Gazebo/Grey</material>
    <gravity>true</gravity>
  </gazebo>
  <gazebo reference="Link4_terabot">
    <material>Gazebo/Black</material>
    <gravity>true</gravity>
  </gazebo>
  <gazebo reference="Link5_terabot">
    <material>Gazebo/Black</material>
    <gravity>true</gravity>
  </gazebo>
  <gazebo reference="Link6_terabot">
    <material>Gazebo/Grey</material>
    <gravity>true</gravity>
  </gazebo>
  <gazebo reference="Link7_terabot">
    <material>Gazebo/Black</material>
    <gravity>true</gravity>
  </gazebo>
  <gazebo reference="Link8_terabot">
    <material>Gazebo/Grey</material>
    <gravity>true</gravity>
  </gazebo>
  <gazebo reference="Link9_terabot">
    <material>Gazebo/Grey</material>
    <gravity>true</gravity>
  </gazebo>
  <gazebo reference="Link91_terabot">
    <material>Gazebo/Black</material>
    <gravity>true</gravity>
  </gazebo>
  <gazebo reference="Link92_terabot">
    <material>Gazebo/Black</material>
    <gravity>true</gravity>
  </gazebo>
  <link name="base_link_terabot">
  </link>
  <link name="Link0_terabot">
    <inertial>
      <origin rpy="0 0 0" xyz="-0.047561 0.016332 0.034298"/>
      <mass value="1.2184"/>
      <inertia ixx="0.0020966" ixy="-0.00096397" ixz="-0.00095822" iyy="0.0070416" iyz="0.00034897" izz="0.0066046"/>
    </inertial>
    <visual>
      <origin rpy="0 0 0" xyz="0 0 0"/>
      <geometry>
        <mesh filename="package://terabot_description/meshes/base_link_terabot.dae"/>
      </geometry>
      <material name="">
        <color rgba="0.79216 0.81961 0.93333 1"/>
      </material>
    </visual>
    <collision>
      <origin rpy="0 0 0" xyz="0 0 0"/>
      <geometry>
        <mesh filename="package://terabot_description/meshes/base_link_terabot.dae"/>
      </geometry>
    </collision>
  </link>
  <joint name="j0_tera" type="fixed">
    <origin rpy="0.0 0.0 0.0" xyz="0.0 0.0 0.0"/>
    <parent link="base_link_terabot"/>
    <child link="Link0_terabot"/>
    <axis xyz="0 0 0"/>
  </joint>
  <link name="Link1_terabot">
    <inertial>
      <origin rpy="0 0 0" xyz="-7.6546E-08 0.040344 -0.04514"/>
      <mass value="0.69822"/>
      <inertia ixx="0.0020624" ixy="-1.4864E-10" ixz="-4.1417E-11" iyy="0.0013995" iyz="0.00069864" izz="0.0011909"/>
    </inertial>
    <visual>
      <origin rpy="0 0 0" xyz="0 0 0"/>
      <geometry>
        <mesh filename="package://terabot_description/meshes/Link1_terabot.dae"/>
      </geometry>
      <material name="">
        <color rgba="0 0 1 1"/>
      </material>
    </visual>
    <collision>
      <origin rpy="0 0 0" xyz="0 0 0"/>
      <geometry>
        <mesh filename="package://terabot_description/meshes/Link1_terabot.dae"/>
      </geometry>
      <contact_coefficients kd="1.0" kp="1000.0" mu="0"/>
    </collision>
  </link>
  <joint name="j1_tera" type="revolute">
    <origin rpy="-7.7739E-17 4.1954E-17 1.8388E-16" xyz="0 0 0.19178"/>
    <!-- parent
      link="base_link_terabot" / -->
    <parent link="Link0_terabot"/>
    <child link="Link1_terabot"/>
    <axis xyz="0 0 -1"/>
    <limit effort="100.0" lower="-2.96706" upper="2.96706" velocity="3.0"/>
    <dynamics damping="0.5" friction="0.5"/>
  </joint>
  <transmission name="j1_trans">
    <type>transmission_interface/SimpleTransmission</type>
    <joint name="j1_tera"/>
    <actuator name="j1_motor">
      <hardwareInterface>EffortJointInterface</hardwareInterface>
      <mechanicalReduction>250.0</mechanicalReduction>
      <motorTorqueConstant>5.0</motorTorqueConstant>
    </actuator>
  </transmission>
  <link name="Link2_terabot">
    <inertial>
      <origin rpy="0 0 0" xyz="0.00360761399982772 -0.00661170134938888 0.011819360433878"/>
      <mass value="0.514917834480378"/>
      <inertia ixx="0.00054584574210388" ixy="3.70809510538145E-06" ixz="3.73133401577889E-05" iyy="0.00061754104586304" iyz="2.90057761867086E-05" izz="0.000521943402494022"/>
    </inertial>
    <visual>
      <origin rpy="0 0 0" xyz="0 0 0"/>
      <geometry>
        <mesh filename="package://terabot_description/meshes/Link2_terabot.dae"/>
      </geometry>
      <material name="">
        <color rgba="0.792156862745098 0.819607843137255 0.933333333333333 1"/>
      </material>
    </visual>
    <collision>
      <origin rpy="0 0 0" xyz="0 0 0"/>
      <geometry>
        <mesh filename="package://terabot_description/meshes/Link2_terabot.dae"/>
      </geometry>
      <contact_coefficients kd="1.0" kp="1000.0" mu="0"/>
    </collision>
  </link>
  <joint name="j2_tera" type="revolute">
    <origin rpy="-2.55370805830961E-18 -1.5708 2.39378218480349E-16" xyz="0 0.00939800000000001 0"/>
    <parent link="Link1_terabot"/>
    <child link="Link2_terabot"/>
    <axis xyz="0 -1 0"/>
    <!-- limit effort="100" velocity="100" upper="0" lower="-1.6557984366"/ -->
    <limit effort="100.0" lower="-2.094395102" upper="0" velocity="3.0"/>
    <dynamics damping="0.5" friction="0.5"/>
  </joint>
  <transmission name="j2_trans">
    <type>transmission_interface/SimpleTransmission</type>
    <joint name="j2_tera"/>
    <actuator name="j2_motor">
      <hardwareInterface>EffortJointInterface</hardwareInterface>
      <mechanicalReduction>250.0</mechanicalReduction>
      <motorTorqueConstant>5.0</motorTorqueConstant>
    </actuator>
  </transmission>
  <link name="Link3_terabot">
    <inertial>
      <origin rpy="0 0 0" xyz="0.15687 -1.7347E-18 0"/>
      <mass value="0.80481"/>
      <inertia ixx="0.00032858" ixy="1.3766E-20" ixz="8.5076E-20" iyy="0.006766" iyz="4.5195E-33" izz="0.006766"/>
    </inertial>
    <visual>
      <origin rpy="0 0 0" xyz="0 0 0"/>
      <geometry>
        <mesh filename="package://terabot_description/meshes/Link3_terabot.dae"/>
      </geometry>
      <material name="">
        <color rgba="0.50196 0.50196 0.50196 1"/>
      </material>
    </visual>
    <collision>
      <origin rpy="0 0 0" xyz="0 0 0"/>
      <geometry>
        <mesh filename="package://terabot_description/meshes/Link3_terabot.dae"/>
      </geometry>
      <contact_coefficients kd="1.0" kp="1000.0" mu="0"/>
    </collision>
  </link>
  <joint name="j3_tera" type="fixed">
    <origin rpy="1.40354206690261E-18 -1.21049302766977E-16 -6.59624157360192E-19" xyz="0.0526796 0 0.0351028"/>
    <parent link="Link2_terabot"/>
    <child link="Link3_terabot"/>
    <axis xyz="0 0 0"/>
  </joint>
  <link name="Link4_terabot">
    <inertial>
      <origin rpy="0 0 0" xyz="0.00360761399982767 -0.00661170134938889 0.011819360433878"/>
      <mass value="0.514917834480377"/>
      <inertia ixx="0.000545845742103879" ixy="3.70809510538146E-06" ixz="3.73133401577888E-05" iyy="0.00061754104586304" iyz="2.90057761867086E-05" izz="0.00052194340249402"/>
    </inertial>
    <visual>
      <origin rpy="0 0 0" xyz="0 0 0"/>
      <geometry>
        <mesh filename="package://terabot_description/meshes/Link4_terabot.dae"/>
      </geometry>
      <material name="">
        <color rgba="0.792156862745098 0.819607843137255 0.933333333333333 1"/>
      </material>
    </visual>
    <collision>
      <origin rpy="0 0 0" xyz="0 0 0"/>
      <geometry>
        <mesh filename="package://terabot_description/meshes/Link4_terabot.dae"/>
      </geometry>
      <contact_coefficients kd="1.0" kp="1000.0" mu="0"/>
    </collision>
  </link>
  <joint name="j4_tera" type="fixed">
    <origin rpy="-7.0187E-19 1.1931E-16 -3.1416" xyz="0.36642 0 -0.035103"/>
    <parent link="Link3_terabot"/>
    <child link="Link4_terabot"/>
    <axis xyz="0 0 0"/>
  </joint>
  <link name="Link5_terabot">
    <inertial>
      <origin rpy="0 0 0" xyz="0.00396009206422587 -0.00204596321606813 0.00468740955382979"/>
      <mass value="0.306377227266223"/>
      <inertia ixx="0.000228823727490413" ixy="2.48236491046025E-06" ixz="3.82925400547741E-05" iyy="0.000279893828628435" iyz="2.93789992467469E-06" izz="0.000215727716562232"/>
    </inertial>
    <visual>
      <origin rpy="0 0 0" xyz="0 0 0"/>
      <geometry>
        <mesh filename="package://terabot_description/meshes/Link5_terabot.dae"/>
      </geometry>
      <material name="">
        <color rgba="0.501960784313725 0.501960784313725 1 1"/>
      </material>
    </visual>
    <collision>
      <origin rpy="0 0 0" xyz="0 0 0"/>
      <geometry>
        <mesh filename="package://terabot_description/meshes/Link5_terabot.dae"/>
      </geometry>
      <contact_coefficients kd="1.0" kp="1000.0" mu="0"/>
    </collision>
  </link>
  <joint name="j5_tera" type="revolute">
    <origin rpy="-5.88385113537159E-18 -1.1651481832801E-13 -3.14159265358979" xyz="0 0.0582295 0"/>
    <parent link="Link4_terabot"/>
    <child link="Link5_terabot"/>
    <axis xyz="0 -1 0"/>
    <!-- limit effort="100" velocity="100" upper="2.96705" lower="-2.82743"/ -->
    <limit effort="100.0" lower="-2.7928224140" upper="2.79208312055332" velocity="3.0"/>
    <dynamics damping="0.5" friction="0.5"/>
  </joint>
  <transmission name="j5_trans">
    <type>transmission_interface/SimpleTransmission</type>
    <joint name="j5_tera"/>
    <actuator name="j5_motor">
      <hardwareInterface>EffortJointInterface</hardwareInterface>
      <mechanicalReduction>250.0</mechanicalReduction>
      <motorTorqueConstant>5.0</motorTorqueConstant>
    </actuator>
  </transmission>
  <link name="Link6_terabot">
    <inertial>
      <origin rpy="0 0 0" xyz="0.13782 1.3878E-17 -2.7756E-17"/>
      <mass value="0.49365"/>
      <inertia ixx="0.00014071" ixy="-2.2644E-20" ixz="3.7837E-20" iyy="0.0031959" iyz="5.662E-32" izz="0.0031959"/>
    </inertial>
    <visual>
      <origin rpy="0 0 0" xyz="0 0 0"/>
      <geometry>
        <mesh filename="package://terabot_description/meshes/Link6_terabot.dae"/>
      </geometry>
      <material name="">
        <color rgba="0.50196 0.50196 0.50196 1"/>
      </material>
    </visual>
    <collision>
      <origin rpy="0 0 0" xyz="0 0 0"/>
      <geometry>
        <mesh filename="package://terabot_description/meshes/Link6_terabot.dae"/>
      </geometry>
      <contact_coefficients kd="1.0" kp="1000.0" mu="0"/>
    </collision>
  </link>
  <joint name="j6_tera" type="fixed">
    <origin rpy="-1.3632E-16 1.1663E-13 -1.5728E-29" xyz="0.04445 0 0.035103"/>
    <parent link="Link5_terabot"/>
    <child link="Link6_terabot"/>
    <axis xyz="0 0 0"/>
  </joint>
  <link name="Link7_terabot">
    <inertial>
      <origin rpy="0 0 0" xyz="-0.00373246826278584 -0.00487492974322868 0.00828543325408726"/>
      <mass value="0.28946235297199"/>
      <inertia ixx="0.00020686291669505" ixy="-8.44907042573481E-07" ixz="-2.05362199435504E-05" iyy="0.000242748125008776" iyz="9.93297893033502E-06" izz="0.000201191399295878"/>
    </inertial>
    <visual>
      <origin rpy="0 0 0" xyz="0 0 0"/>
      <geometry>
        <mesh filename="package://terabot_description/meshes/Link7_terabot.dae"/>
      </geometry>
      <material name="">
        <color rgba="0.501960784313725 0 0 1"/>
      </material>
    </visual>
    <collision>
      <origin rpy="0 0 0" xyz="0 0 0"/>
      <geometry>
        <mesh filename="package://terabot_description/meshes/Link7_terabot.dae"/>
      </geometry>
      <contact_coefficients kd="1.0" kp="1000.0" mu="0"/>
    </collision>
  </link>
  <joint name="j7_tera" type="fixed">
    <origin rpy="2.2039E-16 -4.9001E-17 -3.3933E-16" xyz="0.32009 0 -0.028753"/>
    <parent link="Link6_terabot"/>
    <child link="Link7_terabot"/>
    <axis xyz="0 0 0"/>
  </joint>
  <link name="Link8_terabot">
    <inertial>
      <origin rpy="0 0 0" xyz="0.0 0.0 0.0"/>
      <mass value="0.5"/>
      <inertia ixx="0.5" ixy="0.0" ixz="0.0" iyy="0.5" iyz="0.0" izz="0.5"/>
    </inertial>
    <visual>
      <origin rpy="0 0 0" xyz="0 0 0"/>
      <geometry>
        <mesh filename="package://terabot_description/meshes/Link8_terabot.dae"/>
      </geometry>
      <material name="">
        <color rgba="0 0.75294 0 1"/>
      </material>
    </visual>
    <collision>
      <origin rpy="0 0 0" xyz="0 0 0"/>
      <geometry>
        <mesh filename="package://terabot_description/meshes/Link8_terabot.dae"/>
      </geometry>
      <contact_coefficients kd="1.0" kp="1000.0" mu="0"/>
    </collision>
  </link>
  <joint name="j8_tera" type="revolute">
    <origin rpy="-2.759E-16 4.5532E-17 0" xyz="0 0.04699 0"/>
    <parent link="Link7_terabot"/>
    <child link="Link8_terabot"/>
    <axis xyz="0 -1 0"/>
    <limit effort="100.0" lower="-2.616921" upper="2.26987185" velocity="3.0"/>
    <dynamics damping="0.5" friction="0.5"/>
  </joint>
  <transmission name="j8_trans">
    <type>transmission_interface/SimpleTransmission</type>
    <joint name="j8_tera"/>
    <actuator name="j8_motor">
      <hardwareInterface>EffortJointInterface</hardwareInterface>
      <mechanicalReduction>1</mechanicalReduction>
      <motorTorqueConstant>1</motorTorqueConstant>
    </actuator>
  </transmission>
  <link name="Link9_terabot">
    <inertial>
      <origin rpy="0 0 0" xyz="0.0 0.0 0.0"/>
      <mass value="0.2735"/>
      <inertia ixx="0.2735" ixy="0.0" ixz="0.0" iyy="0.2735" iyz="0.0" izz="0.2735"/>
    </inertial>
    <visual>
      <origin rpy="0 0 0" xyz="0 0 0"/>
      <geometry>
        <mesh filename="package://terabot_description/meshes/Link9_terabot.dae"/>
      </geometry>
      <material name="">
        <color rgba="0.79216 0.81961 0.93333 1"/>
      </material>
    </visual>
    <collision>
      <origin rpy="0 0 0" xyz="0 0 0"/>
      <geometry>
        <mesh filename="package://terabot_description/meshes/Link9_terabot.dae"/>
      </geometry>
      <contact_coefficients kd="1.0" kp="1000.0" mu="0"/>
    </collision>
  </link>
  <joint name="j9_tera" type="revolute">
    <origin rpy="3.14159265359 0 0" xyz="0.0769366 0 0.0328168"/>
    <parent link="Link8_terabot"/>
    <child link="Link9_terabot"/>
    <axis xyz="1 0 0"/>
    <limit effort="100.0" lower="-2.791663" upper="2.791663" velocity="3.0"/>
    <dynamics damping="0.5" friction="0.5"/>
  </joint>
  <transmission name="j9_trans">
    <type>transmission_interface/SimpleTransmission</type>
    <joint name="j9_tera"/>
    <actuator name="j9_motor">
      <hardwareInterface>EffortJointInterface</hardwareInterface>
      <mechanicalReduction>250.0</mechanicalReduction>
      <motorTorqueConstant>5.0</motorTorqueConstant>
    </actuator>
  </transmission>
  <link name="Link91_terabot">
    <inertial>
      <origin rpy="0 0 0" xyz="0.0 0.0 0.0"/>
      <mass value="0.03"/>
      <inertia ixx="0.03" ixy="0.0" ixz="0.0" iyy="0.03" iyz="0.0" izz="0.03"/>
    </inertial>
    <visual>
      <origin rpy="0 0 0" xyz="0 0 0"/>
      <geometry>
        <mesh filename="package://terabot_description/meshes/Link9-1_terabot.dae"/>
      </geometry>
      <material name="">
        <color rgba="0.792156862745098 0.819607843137255 0.933333333333333 1"/>
      </material>
    </visual>
    <collision>
      <origin rpy="0 0 0" xyz="0 0 0"/>
      <geometry>
        <mesh filename="package://terabot_description/meshes/Link9-1_terabot.dae"/>
      </geometry>
    </collision>
  </link>
  <joint name="j91_tera" type="revolute">
    <origin rpy="3.0028E-16 5.9154E-22 2.2204E-16" xyz="0.097993 0.028575 0"/>
    <parent link="Link9_terabot"/>
    <child link="Link91_terabot"/>
    <axis xyz="0 0 -1"/>
    <limit effort="100.0" lower="-1.0" upper="1.0" velocity="3.0"/>
    <dynamics damping="0.5" friction="0.5"/>
  </joint>
  <transmission name="j91_trans">
    <type>transmission_interface/SimpleTransmission</type>
    <joint name="j91_tera"/>
    <actuator name="j91_motor">
      <hardwareInterface>EffortJointInterface</hardwareInterface>
      <mechanicalReduction>1.0</mechanicalReduction>
      <motorTorqueConstant>1.0</motorTorqueConstant>
    </actuator>
  </transmission>
  <link name="Link92_terabot">
    <inertial>
      <origin rpy="0 0 0" xyz="0.0 0.0 0.0"/>
      <mass value="0.03"/>
      <inertia ixx="0.03" ixy="0.0" ixz="0.0" iyy="0.03" iyz="0.0" izz="0.03"/>
    </inertial>
    <visual>
      <origin rpy="0 0 0" xyz="0 0 0"/>
      <geometry>
        <mesh filename="package://terabot_description/meshes/Link9-2_terabot.dae"/>
      </geometry>
      <material name="">
        <color rgba="0.792156862745098 0.819607843137255 0.933333333333333 1"/>
      </material>
    </visual>
    <collision>
      <origin rpy="0 0 0" xyz="0 0 0"/>
      <geometry>
        <mesh filename="package://terabot_description/meshes/Link9-2_terabot.dae"/>
      </geometry>
    </collision>
  </link>
  <joint name="j92_tera" type="revolute">
    <origin rpy="3.0028E-16 7.477E-22 -5.1764E-15" xyz="0.097993 -0.028575 0"/>
    <parent link="Link9_terabot"/>
    <child link="Link92_terabot"/>
    <axis xyz="0 0 -1"/>
    <limit effort="100.0" lower="-1.0" upper="1.0" velocity="3.0"/>
    <dynamics damping="0.5" friction="0.5"/>
  </joint>
  <transmission name="j92_trans">
    <type>transmission_interface/SimpleTransmission</type>
    <joint name="j92_tera"/>
    <actuator name="j92_motor">
      <hardwareInterface>EffortJointInterface</hardwareInterface>
      <mechanicalReduction>1.0</mechanicalReduction>
      <motorTorqueConstant>1.0</motorTorqueConstant>
    </actuator>
  </transmission>
  <link name="tcp_link1">
    <visual>
      <origin rpy="0 0 0" xyz="0 0 0"/>
      <geometry>
        <sphere radius="0.01"/>
      </geometry>
      <material name="red">
        <color rgba="1 0 0 1"/>
      </material>
    </visual>
  </link>
  <joint name="tcp_joint1" type="fixed">
    <origin rpy="0.0 0.0 0.0" xyz="0.2 0.0 0.0"/>
    <parent link="Link9_terabot"/>
    <child link="tcp_link1"/>
    <axis xyz="0 0 0"/>
  </joint>
  <link name="tcp_link2">
    <visual>
      <origin rpy="0 0 0" xyz="0 0 0"/>
      <geometry>
        <sphere radius="0.01"/>
      </geometry>
      <material name="green">
        <color rgba="0 1 0 1"/>
      </material>
    </visual>
  </link>
  <joint name="tcp_joint2" type="fixed">
    <origin rpy="0.0 0.0 0.0" xyz="0.0 0.0 0.0"/>
    <parent link="Link9_terabot"/>
    <child link="tcp_link2"/>
    <axis xyz="0 0 0"/>
  </joint>
  <link name="tcp_link3">
    <visual>
      <origin rpy="0 0 0" xyz="0 0 0"/>
      <geometry>
        <sphere radius="0.01"/>
      </geometry>
      <material name="blue">
        <color rgba="0 0 1 1"/>
      </material>
    </visual>
  </link>
  <joint name="tcp_joint3" type="fixed">
    <origin rpy="0.0 0.0 0.0" xyz="0.1 -0.025 -0.05"/>
    <parent link="Link9_terabot"/>
    <child link="tcp_link3"/>
    <axis xyz="0 0 0"/>
  </joint>
  <link name="tcp_link4">
    <visual>
      <origin rpy="0 0 0" xyz="0 0 0"/>
      <geometry>
        <sphere radius="0.01"/>
      </geometry>
      <material name="yellow">
        <color rgba="1 1 0 1"/>
      </material>
    </visual>
  </link>
  <joint name="tcp_joint4" type="fixed">
    <origin rpy="0.0 0.0 0.0" xyz="0.0 0.0 0.0"/>
    <parent link="Link9_terabot"/>
    <child link="tcp_link4"/>
    <axis xyz="0 0 0"/>
  </joint>
  <link name="tcp_link5">
    <visual>
      <origin rpy="0 0 0" xyz="0 0 0"/>
      <geometry>
        <sphere radius="0.01"/>
      </geometry>
      <material name="cyan">
        <color rgba="0 1 1 1"/>
      </material>
    </visual>
  </link>
  <joint name="tcp_joint5" type="fixed">
    <origin rpy="0.0 0.0 0.0" xyz="0.0 0.0 0.0"/>
    <parent link="Link9_terabot"/>
    <child link="tcp_link5"/>
    <axis xyz="0 0 0"/>
  </joint>
  <joint name="base_footprint_terabot_joint" type="fixed">
    <origin rpy="0 0 0" xyz="-0.220 0 0.410"/>
    <parent link="base_link"/>
    <child link="base_link_terabot"/>
  </joint>
</robot>
