<?xml version="1.0"?>
<sdf version="1.3">
  <model name="summit_xl">
	<pose>0 0 0.2 0 0 0</pose>
    <static>false</static>
    <link name="base_footprint">
      <pose>0.000000 0.000000 0.050000 0.000000 0.000000 0.000000</pose>
      <inertial>
        <!-- pose>0.000000 0.000000 0.05 0.000000 0.000000 0.000000</pose-->
        <mass>25.012100</mass>
        <inertia>
          <ixx>1.456670</ixx>
          <ixy>0.004000</ixy>
          <ixz>0.000000</ixz>
          <iyy>6.918470</iyy>
          <iyz>0.000000</iyz>
          <izz>6.126300</izz>
        </inertia>
      </inertial>
      <collision name="collision">
        <geometry>
          <mesh>
            <scale>1.000000 1.000000 1.000000</scale>
            <uri>model://summit_xl_description/meshes/summit_xl_chassis_cam1.stl</uri>
          </mesh>
        </geometry>
        <surface>
          <contact>
            <ode/>
          </contact>
          <friction>
            <ode/>
          </friction>
        </surface>
      </collision>
      <visual name="visual">
        <geometry>
          <mesh>
            <scale>1.000000 1.000000 1.000000</scale>
            <uri>model://summit_xl_description/meshes/summit_xl_chassis_cam1.stl</uri>
          </mesh>
        </geometry>
        <material>
          <script>
            <name>Gazebo/Red</name>
            <uri>__default__</uri>
          </script>
        </material>
      </visual>
      <!-- velocity_decay>
        <linear>0.000000</linear>
        <angular>0.000000</angular>
      </velocity_decay>
      <velocity_decay>
        <linear>0.000000</linear>
        <angular>0.000000</angular>
      </velocity_decay>
      <gravity>1</gravity>
      <velocity_decay>
        <linear>0.000000</linear>
        <angular>0.000000</angular>
      </velocity_decay>
      <self_collide>0</self_collide-->
    </link>
    <link name="back_left_wheel">
      <pose>-0.223000 0.154000 0.050000 0.000000 0.000000 0.000000</pose>
      <inertial>
        <pose>0.000000 0.000000 0.000000 0.000000 0.000000 0.000000</pose>
        <mass>1.250000</mass>
        <inertia>
          <ixx>0.010937</ixx>
          <ixy>0.000000</ixy>
          <ixz>0.000000</ixz>
          <iyy>0.021125</iyy>
          <iyz>0.000000</iyz>
          <izz>0.010937</izz>
        </inertia>
      </inertial>
      <collision name="back_left_wheel_collision">
        <pose>0.000000 0.000000 0.000000 0.000000 0.000000 0.000000</pose>
        <geometry>
          <mesh>
            <scale>1.000000 1.000000 1.000000</scale>
            <uri>model://summit_xl_description/meshes/summit_xl_wheel.stl</uri>
          </mesh>
        </geometry>
        <surface>
          <contact>
            <ode/>
          </contact>
          <friction>
            <ode>
              <mu>100.000000</mu>
              <mu2>100.000000</mu2>
              <fdir1>1.000000 0.000000 0.000000</fdir1>
            </ode>
          </friction>
        </surface>
      </collision>
      <visual name="back_left_wheel_vis">
        <pose>0.000000 0.000000 0.000000 0.000000 0.000000 0.000000</pose>
        <geometry>
          <mesh>
            <scale>1.000000 1.000000 1.000000</scale>
            <uri>model://summit_xl_description/meshes/summit_xl_wheel.stl</uri>
          </mesh>
        </geometry>
        <material>
          <script>
            <name>Gazebo/Grey</name>
            <uri>__default__</uri>
          </script>
        </material>
      </visual>
      <gravity>1</gravity>
      <velocity_decay>
        <linear>0.000000</linear>
        <angular>0.000000</angular>
      </velocity_decay>
      <self_collide>0</self_collide>
    </link>
  
    <joint name="left_rear" type="revolute">
      <child>back_left_wheel</child>
      <parent>base_footprint</parent>
      <axis>
        <xyz>0.000000 1.000000 0.000000</xyz>
        <limit>
          <lower>-10000000000000000.000000</lower>
          <upper>10000000000000000.000000</upper>
        </limit>
        <dynamics/>
      </axis>
    </joint>
        
    <link name="back_right_wheel">
      <pose>-0.223000 -0.154000 0.050000 0.000000 0.000000 -3.141590</pose>
      <inertial>
        <pose>0.000000 0.000000 0.000000 0.000000 0.000000 0.000000</pose>
        <mass>1.250000</mass>
        <inertia>
          <ixx>0.010937</ixx>
          <ixy>0.000000</ixy>
          <ixz>0.000000</ixz>
          <iyy>0.021125</iyy>
          <iyz>0.000000</iyz>
          <izz>0.010937</izz>
        </inertia>
      </inertial>
      <collision name="back_right_wheel_collision">
        <pose>0.000000 0.000000 0.000000 0.000000 0.000000 0.000000</pose>
        <geometry>
          <mesh>
            <scale>1.000000 1.000000 1.000000</scale>
            <uri>model://summit_xl_description/meshes/summit_xl_wheel.stl</uri>
          </mesh>
        </geometry>
        <surface>
          <contact>
            <ode/>
          </contact>
          <friction>
            <ode>
              <mu>100.000000</mu>
              <mu2>100.000000</mu2>
              <fdir1>1.000000 0.000000 0.000000</fdir1>
            </ode>
          </friction>
        </surface>
      </collision>
      <visual name="back_right_wheel_vis">
        <pose>0.000000 0.000000 0.000000 0.000000 0.000000 0.000000</pose>
        <geometry>
          <mesh>
            <scale>1.000000 1.000000 1.000000</scale>
            <uri>model://summit_xl_description/meshes/summit_xl_wheel.stl</uri>
          </mesh>
        </geometry>
        <material>
          <script>
            <name>Gazebo/Grey</name>
            <uri>__default__</uri>
          </script>
        </material>
      </visual>
      <gravity>1</gravity>
      <velocity_decay>
        <linear>0.000000</linear>
        <angular>0.000000</angular>
      </velocity_decay>
      <self_collide>0</self_collide>
    </link>
    
    <joint name="right_rear" type="revolute">
      <child>back_right_wheel</child>
      <parent>base_footprint</parent>
      <axis>
        <xyz>0.000007 -1.000000 0.000000</xyz>
        <limit>
          <lower>-10000000000000000.000000</lower>
          <upper>10000000000000000.000000</upper>
        </limit>
        <dynamics/>
      </axis>
    </joint>
    
    
    <link name="front_left_wheel">
      <pose>0.223000 0.154000 0.050000 0.000000 0.000000 0.000000</pose>
      <inertial>
        <pose>0.000000 0.000000 0.000000 0.000000 0.000000 0.000000</pose>
        <mass>1.250000</mass>
        <inertia>
          <ixx>0.010937</ixx>
          <ixy>0.000000</ixy>
          <ixz>0.000000</ixz>
          <iyy>0.021125</iyy>
          <iyz>0.000000</iyz>
          <izz>0.010937</izz>
        </inertia>
      </inertial>
      <collision name="front_left_wheel_collision">
        <pose>0.000000 0.000000 0.000000 0.000000 0.000000 0.000000</pose>
        <geometry>
          <mesh>
            <scale>1.000000 1.000000 1.000000</scale>
            <uri>model://summit_xl_description/meshes/summit_xl_wheel.stl</uri>
          </mesh>
        </geometry>
        <surface>
          <contact>
            <ode/>
          </contact>
          <friction>
            <ode>
              <mu>100.000000</mu>
              <mu2>100.000000</mu2>
              <fdir1>1.000000 0.000000 0.000000</fdir1>
            </ode>
          </friction>
        </surface>
      </collision>
      <visual name="front_left_wheel_vis">
        <pose>0.000000 0.000000 0.000000 0.000000 0.000000 0.000000</pose>
        <geometry>
          <mesh>
            <scale>1.000000 1.000000 1.000000</scale>
            <uri>model://summit_xl_description/meshes/summit_xl_wheel.stl</uri>
          </mesh>
        </geometry>
        <material>
          <script>
            <name>Gazebo/Grey</name>
            <uri>__default__</uri>
          </script>
        </material>
      </visual>
      <gravity>1</gravity>
      <velocity_decay>
        <linear>0.000000</linear>
        <angular>0.000000</angular>
      </velocity_decay>
      <self_collide>0</self_collide>
    </link>
    
    <joint name="left_front" type="revolute">
      <child>front_left_wheel</child>
      <parent>base_footprint</parent>
      <axis>
        <xyz>0.000000 1.000000 0.000000</xyz>
        <limit>
          <lower>-10000000000000000.000000</lower>
          <upper>10000000000000000.000000</upper>
        </limit>
        <dynamics/>
      </axis>
    </joint>
    
    <link name="front_right_wheel">
      <pose>0.223000 -0.154000 0.050000 0.000000 0.000000 -3.141590</pose>
      <inertial>
        <pose>0.000000 0.000000 0.000000 0.000000 0.000000 0.000000</pose>
        <mass>1.250000</mass>
        <inertia>
          <ixx>0.010937</ixx>
          <ixy>0.000000</ixy>
          <ixz>0.000000</ixz>
          <iyy>0.021125</iyy>
          <iyz>0.000000</iyz>
          <izz>0.010937</izz>
        </inertia>
      </inertial>
      <collision name="front_right_wheel_collision">
        <pose>0.000000 0.000000 0.000000 0.000000 0.000000 0.000000</pose>
        <geometry>
          <mesh>
            <scale>1.000000 1.000000 1.000000</scale>
            <uri>model://summit_xl_description/meshes/summit_xl_wheel.stl</uri>
          </mesh>
        </geometry>
        <surface>
          <contact>
            <ode/>
          </contact>
          <friction>
            <ode>
              <mu>100.000000</mu>
              <mu2>100.000000</mu2>
              <fdir1>1.000000 0.000000 0.000000</fdir1>
            </ode>
          </friction>
        </surface>
      </collision>
      <visual name="front_right_wheel_vis">
        <pose>0.000000 0.000000 0.000000 0.000000 0.000000 0.000000</pose>
        <geometry>
          <mesh>
            <scale>1.000000 1.000000 1.000000</scale>
            <uri>model://summit_xl_description/meshes/summit_xl_wheel.stl</uri>
          </mesh>
        </geometry>
        <material>
          <script>
            <name>Gazebo/Grey</name>
            <uri>__default__</uri>
          </script>
        </material>
      </visual>
      <gravity>1</gravity>
      <velocity_decay>
        <linear>0.000000</linear>
        <angular>0.000000</angular>
      </velocity_decay>
      <self_collide>0</self_collide>
    </link>
    
    <joint name="right_front" type="revolute">
      <child>front_right_wheel</child>
      <parent>base_footprint</parent>
      <axis>
        <xyz>0.000007 -1.000000 0.000000</xyz>
        <limit>
          <lower>-10000000000000000.000000</lower>
          <upper>10000000000000000.000000</upper>
        </limit>
        <dynamics/>
      </axis>
    </joint>
    
    
    <!--plugin name="SkidSteerDrivePlugin" filename="libSkidSteerDrivePlugin.so">
      <right_front>right_front</right_front>
      <right_rear>right_rear</right_rear>
      <left_front>left_front</left_front>
      <left_rear>left_rear</left_rear>
      <MaxForce>5.0</MaxForce>
    </plugin-->

    <plugin name="summit_xl_plugin" filename="libsummit_xl_plugin.so">
          <!-- parameters -->
    </plugin>
	
    <include>
      <uri>model://hokuyo</uri>
      <pose>0.0 0 0.35 0 0 0</pose>
    </include>
	
    <joint name="hokuyo_laser_joint" type="revolute"> 
      <child>hokuyo::link</child>
      <parent>base_footprint</parent>
	  <axis>
		<xyz>0 0 1</xyz>
		<limit>
		  <upper>0</upper>
		  <lower>0</lower>
		</limit>
          </axis>
    </joint>

  </model>
</sdf>
