<?xml version="1.0"?>
<!--
Copyright (c) 2012, Siddhant Ahuja/WAVELab, Ryan Gariepy/Clearpath Robotics
All rights reserved.

Redistribution and use in source and binary forms, with or without
modification, are permitted provided that the following conditions are met:
    * Redistributions of source code must retain the above copyright
      notice, this list of conditions and the following disclaimer.
    * Redistributions in binary form must reproduce the above copyright
      notice, this list of conditions and the following disclaimer in the
      documentation and/or other materials provided with the distribution.
    * Neither the name of Clearpath Robotics nor the
      names of its contributors may be used to endorse or promote products
      derived from this software without specific prior written permission.

THIS SOFTWARE IS PROVIDED BY THE COPYRIGHT HOLDERS AND CONTRIBUTORS "AS IS" AND
ANY EXPRESS OR IMPLIED WARRANTIES, INCLUDING, BUT NOT LIMITED TO, THE IMPLIED
WARRANTIES OF MERCHANTABILITY AND FITNESS FOR A PARTICULAR PURPOSE ARE
DISCLAIMED. IN NO EVENT SHALL THE COPYRIGHT HOLDERS BE LIABLE FOR ANY
DIRECT, INDIRECT, INCIDENTAL, SPECIAL, EXEMPLARY, OR CONSEQUENTIAL DAMAGES
(INCLUDING, BUT NOT LIMITED TO, PROCUREMENT OF SUBSTITUTE GOODS OR SERVICES;
LOSS OF USE, DATA, OR PROFITS; OR BUSINESS INTERRUPTION) HOWEVER CAUSED AND
ON ANY THEORY OF LIABILITY, WHETHER IN CONTRACT, STRICT LIABILITY, OR TORT
(INCLUDING NEGLIGENCE OR OTHERWISE) ARISING IN ANY WAY OUT OF THE USE OF THIS
SOFTWARE, EVEN IF ADVISED OF THE POSSIBILITY OF SUCH DAMAGE.

This program contains the description of the robot wheel model for Clearpath Husky A200
-->
<robot xmlns:sensor="http://playerstage.sourceforge.net/gazebo/xmlschema/#sensor"
	xmlns:controller="http://playerstage.sourceforge.net/gazebo/xmlschema/#controller"
	xmlns:interface="http://playerstage.sourceforge.net/gazebo/xmlschema/#interface"
	xmlns:xacro="http://ros.org/wiki/xacro" name="summit_xl">
	
  <property name="M_PI" value="3.1415926535897931" />
  
  <!--                                                      -->
  <!--         rubber  wheel                                -->
  <!--                                                      -->
  <xacro:macro name="rubber_wheel" params="name parent *origin">

    <joint name="${parent}_${suffix}_wheel_joint" type="continuous">
      <axis xyz="0 1 0" />
      <limit effort="7" velocity="15"/> <!-- alpha tested effort and velocity limits -->
      <safety_controller  k_velocity="10" />
      <dynamics damping="1.0" friction="0.0" />
      <origin xyz="0 ${reflect*caster_wheel_offset_y} 0" rpy="0 0 0" />
      <parent link="${parent}_rotation_link"/>
      <child link="${parent}_${suffix}_wheel_link"/>
    </joint>
    <link name="${parent}_${suffix}_wheel_link">
      <inertial>
        <mass value="0.44036" />
        <origin xyz="0 0 0" />
        <inertia  ixx="0.012411765597" ixy="-0.000711733678" ixz="0.00050272983"
                  iyy="0.015218160428" iyz="-0.000004273467" izz="0.011763977943" />
      </inertial>
      <visual>
        <origin xyz="0 0 0" rpy="0 0 0" />
        <geometry>
          <mesh filename="package://pr2_description/meshes/base_v0/wheel.dae" />
        </geometry>
        
        <material name="Wheel_${suffix}" />
      </visual>
      <collision>
        <origin xyz="0 0 0" rpy="${M_PI/2} 0 0" /> <!-- rotation because cyl. geom primitive has symmetry axis in +x direction -->
        <geometry>
          <cylinder radius="${wheel_radius}" length="${wheel_length}" />
        </geometry>
      </collision>
    </link>


  </xacro:macro>
</robot>
